Traceback (most recent call last):
  File "/Users/rizvi/miniconda3/envs/syed/lib/python3.10/site-packages/jupyter_cache/executors/utils.py", line 51, in single_nb_execution
    executenb(
  File "/Users/rizvi/miniconda3/envs/syed/lib/python3.10/site-packages/nbclient/client.py", line 1204, in execute
    return NotebookClient(nb=nb, resources=resources, km=km, **kwargs).execute()
  File "/Users/rizvi/miniconda3/envs/syed/lib/python3.10/site-packages/nbclient/util.py", line 84, in wrapped
    return just_run(coro(*args, **kwargs))
  File "/Users/rizvi/miniconda3/envs/syed/lib/python3.10/site-packages/nbclient/util.py", line 62, in just_run
    return loop.run_until_complete(coro)
  File "/Users/rizvi/miniconda3/envs/syed/lib/python3.10/asyncio/base_events.py", line 646, in run_until_complete
    return future.result()
  File "/Users/rizvi/miniconda3/envs/syed/lib/python3.10/site-packages/nbclient/client.py", line 663, in async_execute
    await self.async_execute_cell(
  File "/Users/rizvi/miniconda3/envs/syed/lib/python3.10/site-packages/nbclient/client.py", line 965, in async_execute_cell
    await self._check_raise_for_error(cell, cell_index, exec_reply)
  File "/Users/rizvi/miniconda3/envs/syed/lib/python3.10/site-packages/nbclient/client.py", line 862, in _check_raise_for_error
    raise CellExecutionError.from_cell_and_msg(cell, exec_reply_content)
nbclient.exceptions.CellExecutionError: An error occurred while executing the following cell:
------------------
rad_ds = xr.open_mfdataset(output_grid_folder+"/*")
------------------

[0;31m---------------------------------------------------------------------------[0m
[0;31mOSError[0m                                   Traceback (most recent call last)
Input [0;32mIn [18][0m, in [0;36m<cell line: 1>[0;34m()[0m
[0;32m----> 1[0m rad_ds [38;5;241m=[39m [43mxr[49m[38;5;241;43m.[39;49m[43mopen_mfdataset[49m[43m([49m[43moutput_grid_folder[49m[38;5;241;43m+[39;49m[38;5;124;43m"[39;49m[38;5;124;43m/*[39;49m[38;5;124;43m"[39;49m[43m)[49m

File [0;32m~/miniconda3/envs/syed/lib/python3.10/site-packages/xarray/backends/api.py:873[0m, in [0;36mopen_mfdataset[0;34m(paths, chunks, concat_dim, compat, preprocess, engine, data_vars, coords, combine, parallel, join, attrs_file, combine_attrs, **kwargs)[0m
[1;32m    870[0m     paths [38;5;241m=[39m [os[38;5;241m.[39mfspath(p) [38;5;28;01mif[39;00m [38;5;28misinstance[39m(p, os[38;5;241m.[39mPathLike) [38;5;28;01melse[39;00m p [38;5;28;01mfor[39;00m p [38;5;129;01min[39;00m paths]
[1;32m    872[0m [38;5;28;01mif[39;00m [38;5;129;01mnot[39;00m paths:
[0;32m--> 873[0m     [38;5;28;01mraise[39;00m [38;5;167;01mOSError[39;00m([38;5;124m"[39m[38;5;124mno files to open[39m[38;5;124m"[39m)
[1;32m    875[0m [38;5;28;01mif[39;00m combine [38;5;241m==[39m [38;5;124m"[39m[38;5;124mnested[39m[38;5;124m"[39m:
[1;32m    876[0m     [38;5;28;01mif[39;00m [38;5;28misinstance[39m(concat_dim, ([38;5;28mstr[39m, DataArray)) [38;5;129;01mor[39;00m concat_dim [38;5;129;01mis[39;00m [38;5;28;01mNone[39;00m:

[0;31mOSError[0m: no files to open
OSError: no files to open

